Workbook
Name a: #REF!
Name aaaza: #REF!
Name aas: #REF!
Name aee: #REF!
Name avril: #REF!
Name az: #REF!
Name aze: #REF!
Name azezz: #REF!
Name azr: #REF!
Name BD: #REF!
Name BV: #REF!
Name cezcz: #REF!
Name Comparison: #REF!
Name cz: #REF!
Name czczczccz: #REF!
Name cze: #REF!
Name e: #REF!
Name er: #REF!
Name EtatTravaux: '[1]Listes Données'!$B$16:$B$18
Name ferri: #REF!
Name FEV: #REF!
Name FG: #REF!
Name JGVEPVJE: #REF!
Name LKNV: #REF!
Name LNVSEV: #REF!
Name LVEDV: #REF!
Name Mai: #REF!
Name mar: #REF!
Name MOJEGV: #REF!
Name moo: #REF!
Name Myplage: [2]!Tableau2[#Data]
Name NgnEuro: [3]Sheet1!$J$1
Name OENVEVE: #REF!
Name OHEEV: #REF!
Name ok: #REF!
Name ON: #REF!
Name PAR: #REF!
Name PO: #REF!
Name Print_Area_MI: #REF!
Name prn: #REF!
Name REGUL: #REF!
Name RO: #REF!
Name top: #REF!
Name TypeActivités: '[1]Listes Données'!$B$3:$B$8
Name z: #REF!
Name ze: #REF!
Name zeaz: #REF!
Name zeer: #REF!

Sheet PRICING 
B5: Prix indexés FCFA
B6: 2020 | C6: 0.008
B7: ORANGE | C7: MLL | D7: MLL BPCI | E7: Colloc | F7: BTS | G7: BARTER | H7: Athena 1 | I7: Athena 2
B8: gestion existant | C8: 457964.28 | D8: 343473.21 | H8: RTT 10% & rest 21% | I8: 0.18
B9: nvo site terrace | E9: 839131.48 | F9: 839131.48 | G9: 755218.33 | H9: 755218.33 | I9: 688087.81
B10: nvo site : 20m et 32m | E10: 1139274.2 | F10: 1139274.2 | G10: 1025346.8 | H10: 900026.63 | I10: 934204.86
B11: nvo site : 33m et 49m | E11: 1345710.4 | F11: 1345710.4 | G11: 1211139.4 | H11: 1063111.2 | I11: 1103482.5
B12: nvo site : 50m et 75m | E12: 1635284.8 | F12: 1635284.8 | G12: 1471756.3 | H12: 1291875 | I12: 1340933.5
B13: nvo site : 76m et 90m | E13: 2293056.3 | F13: 2293056.3 | G13: 2063750.7 | H13: 1811514.5 | I13: 1880306.2
B14: nvo site : 91m et 105m | E14: 2805559.7 | F14: 2805559.7 | G14: 2525003.7 | H14: 2216392.1 | I14: 2300558.9
B15: Echeance : 30 jrs | E15: 0 | F15: 0 | G15: 0 | H15: 0 | I15: 0
B19: Prix indexés FCFA
B20: 2021 | C20: 0.024 | J20: 18 new sites/Coloc_Nawa
B21: ORANGE | C21: MLL | D21: MLL BPCI | E21: Colloc | F21: BTS | G21: BARTER | H21: Athena 1 | I21: Athena 2 | J21: Colocation_Nawa
B22: gestion existant | C22: 468955.42 | D22: 351716.57 | H22: RTT 10% & rest 21% | I22: 0.18 | J22: 0.15
B23: nvo site terrace | E23: 859270.63 | F23: 859270.63 | G23: 773343.57 | H23: 773343.57 | I23: 704601.92 | J23: 730380.04
B24: nvo site : 20m et 32m | E24: 1166616.8 | F24: 1166616.8 | G24: 1049955.1 | H24: 921627.27 | I24: 956625.78 | J24: 991624.28
B25: nvo site : 33m et 49m | E25: 1378007.5 | F25: 1378007.5 | G25: 1240206.7 | H25: 1088625.9 | I25: 1129966.1 | J25: 1171306.4
B26: nvo site : 50m et 75m | E26: 1674531.6 | F26: 1674531.6 | G26: 1507078.4 | H26: 1322880 | I26: 1373115.9 | J26: 1423351.9
B27: nvo site : 76m et 90m | E27: 2348089.7 | F27: 2348089.7 | G27: 2113280.7 | H27: 1854990.8 | I27: 1925433.5 | J27: 1995876.2
B28: nvo site : 91m et 105m | E28: 2872893.1 | F28: 2872893.1 | G28: 2585603.8 | H28: 2269585.5 | I28: 2355772.3 | J28: 2441959.1
B29: Echeance : 30 jrs | E29: 0 | F29: 0 | G29: 0 | H29: 0 | I29: 0 | J29: 0
B32: Prix indexés FCFA
B33: 2022 | C33: 0.042 | J33: 18 new sites/Coloc_Nawa | K33: 13 new sites/ BTS_Nawa
B34: ORANGE | C34: MLL | D34: MLL BPCI | E34: Colloc | F34: BTS | G34: BARTER | H34: Athena 1 | I34: Athena 2 | J34: Colocation_Nawa | K34: BTS_Nawa
B35: gestion existant | C35: 488651.55 | D35: 366488.66 | H35: RTT 10% & rest 21% | I35: 0.18 | J35: 0.15 | K35: 0.1
B36: nvo site terrace | E36: 895360 | F36: 895360 | G36: 805824 | H36: 805824 | I36: 734195.2 | J36: 761056 | K36: 805824
B37: nvo site : 20m et 32m | E37: 1215614.7 | F37: 1215614.7 | G37: 1094053.2 | H37: 960335.62 | I37: 996804.06 | J37: 1033272.5 | K37: 1094053.2
B38: nvo site : 33m et 49m | E38: 1435883.8 | F38: 1435883.8 | G38: 1292295.4 | H38: 1134348.2 | I38: 1177424.7 | J38: 1220501.2 | K38: 1292295.4
B39: nvo site : 50m et 75m | E39: 1744861.9 | F39: 1744861.9 | G39: 1570375.7 | H39: 1378440.9 | I39: 1430786.8 | J39: 1483132.6 | K39: 1570375.7
B40: nvo site : 76m et 90m | E40: 2446709.4 | F40: 2446709.4 | G40: 2202038.5 | H40: 1932900.4 | I40: 2006301.7 | J40: 2079703 | K40: 2202038.5
B41: nvo site : 91m et 105m | E41: 2993554.6 | F41: 2993554.6 | G41: 2694199.1 | H41: 2364908.1 | I41: 2454714.8 | J41: 2544521.4 | K41: 2694199.1
B42: Echeance : 30 jrs | E42: 0 | F42: 0 | G42: 0 | H42: 0 | I42: 0 | J42: 0 | K42: 0
D45: Projet | E45: Nombre de Sites - Q1.2023 | F45: Commentaire
D46: MLL | E46: 1108 | F46: OK Pour facturation trimestrielle
D47: MLL BPCI | E47: 40 | F47: OK Pour facturation trimestrielle
D48: Colocation | E48: 399 | F48: OK Pour facturation trimestrielle
D49: BTS | E49: 150 | F49: OK Pour facturation trimestrielle
D50: BARTER | E50: 65 | F50: OK Pour facturation trimestrielle
D51: Athena 1 | E51: 193 | F51: OK Pour facturation trimestrielle
...

Sheet SUMMARY ORANGE Q1-2023 INVOICES
B6: FACTURATION PREVISIONNELLE Q1 - 2023 | C6: MOIS | D6: TRIMESTRE HT | E6: TVA | F6: NET A PAYER Q1 -2023
B7: ='OCI-MLL 1108 SIT Q1 -2023'!D12 -> OCI-MLL 1108 SIT Q1 - JANVIER 23 - MARS 23 | C7: =+'OCI-MLL 1108 SIT Q1 -2023'!F15 -> 5.4142592e+08 | D7: =+'OCI-MLL 1108 SIT Q1 -2023'!H15 -> 1.6242778e+09 | E7: =+'OCI-MLL 1108 SIT Q1 -2023'!I15 -> 2.9237e+08 | F7: =+'OCI-MLL 1108 SIT Q1 -2023'!J15 -> 1.9166477e+09
B8: ='OCI-MLL BPCI 22 SIT Q1- 2023'!D11 -> OCI-MLL BPCI 22 SIT Q1 - JANVIER 23 - MARS 23 | C8: =+'OCI-MLL BPCI 22 SIT Q1- 2023'!F15 -> 8062747 | D8: =+'OCI-MLL BPCI 22 SIT Q1- 2023'!H15 -> 24188241 | E8: =+'OCI-MLL BPCI 22 SIT Q1- 2023'!I15 -> 4353883.4 | F8: =+'OCI-MLL BPCI 22 SIT Q1- 2023'!J15 -> 28542124
B9: ='OCI-MLL BPCI 18 SIT Q1 - 2023'!D12 -> OCI-MLL BPCI 18 SIT Q1 - JANVIER 23 - MARS 23 | C9: =+'OCI-MLL BPCI 18 SIT Q1 - 2023'!F15 -> 6596793 | D9: =+'OCI-MLL BPCI 18 SIT Q1 - 2023'!H15 -> 19790379 | E9: =+'OCI-MLL BPCI 18 SIT Q1 - 2023'!I15 -> 3562268.2 | F9: =+'OCI-MLL BPCI 18 SIT Q1 - 2023'!J15 -> 23352647
B10: ='OCI-COLOC 399 SIT Q1 - 2023'!D13 -> OCI-COLOC 399 SIT Q1 - JANVIER 23 - MARS 23 | C10: =+'OCI-COLOC 399 SIT Q1 - 2023'!G14 -> 5.543335e+08 | D10: =+'OCI-COLOC 399 SIT Q1 - 2023'!I14 -> 1.6630005e+09 | E10: =+'OCI-COLOC 399 SIT Q1 - 2023'!J14 -> 2.9934009e+08 | F10: =+'OCI-COLOC 399 SIT Q1 - 2023'!K14 -> 1.9623406e+09
B11: ='OCI-PREST 193 ATHENA 1 Q1- 2023'!D12 -> OCI-PREST 193 ATHENA 1 Q1 - JANVIER 23 - MARS 23 | C11: =+'OCI-PREST 193 ATHENA 1 Q1- 2023'!G15 -> 2.4666948e+08 | D11: =+'OCI-PREST 193 ATHENA 1 Q1- 2023'!I15 -> 7.4000843e+08 | E11: =+'OCI-PREST 193 ATHENA 1 Q1- 2023'!J15 -> 1.3320152e+08 | F11: =+'OCI-PREST 193 ATHENA 1 Q1- 2023'!K15 -> 8.7320994e+08
B12: ='OCI-ATHENA 2-125 SIT Q1- 2023'!E13 -> OCI-ATHENA 2 -125 SIT Q1 - JANVIER 23 - MARS 23 | C12: =+'OCI-ATHENA 2-125 SIT Q1- 2023'!H15 -> 1.3688431e+08 | D12: =+'OCI-ATHENA 2-125 SIT Q1- 2023'!J15 -> 4.1065293e+08 | E12: =+'OCI-ATHENA 2-125 SIT Q1- 2023'!K15 -> 73917527 | F12: =+'OCI-ATHENA 2-125 SIT Q1- 2023'!L15 -> 4.8457045e+08
B13: ='OCI-BTS 150 SIT Q1 - 2023'!D13 -> OCI-BTS 150 SIT Q1 - JANVIER 23 - MARS 23 | C13: =+'OCI-BTS 150 SIT Q1 - 2023'!G15 -> 2.2900477e+08 | D13: =+'OCI-BTS 150 SIT Q1 - 2023'!I15 -> 6.8701432e+08 | E13: =+'OCI-BTS 150 SIT Q1 - 2023'!J15 -> 1.2366258e+08 | F13: =+'OCI-BTS 150 SIT Q1 - 2023'!K15 -> 8.106769e+08
B14: ='OCI-65 SIT BARTER Q1 - 2023'!D13 -> OCI-65 SIT BARTER Q1 - JANVIER 23 - MARS 23 | C14: =+'OCI-65 SIT BARTER Q1 - 2023'!G15 -> 92355143 | D14: =+'OCI-65 SIT BARTER Q1 - 2023'!I15 -> 2.7706543e+08 | E14: =+'OCI-65 SIT BARTER Q1 - 2023'!J15 -> 49871777 | F14: =+'OCI-65 SIT BARTER Q1 - 2023'!K15 -> 3.2693721e+08
D15: MOIS | E15: TVA | F15: NET A PAYER
D16: 38963846 | E16: 7013492.2 | F16: 45977338
B17: OCI-33 SITES TIERS JANVIER 23
B18: ORANGE TOTAL FACTURES - JANVIER 23 | C18: =+F7+F8+F9+F10+F11+F12+F13+F14+F16 -> 6.4722549e+09
D20: MOIS | E20: TVA | F20: NET A PAYER
B21: OCI-33 SITES TIERS FEVRIER 23 | D21: 38963846 | E21: 7013492.2 | F21: 45977338
B22: OCI-33 SITES TIERS MARS 23 | D22: 38963846 | E22: 7013492.2 | F22: 45977338
D24: MOIS | E24: TVA | F24: NET A PAYER
A25: Régulier/ par Trimestre | B25: OCI- Avoir Loyer Ex BARTER Q1 -2023 | D25: -3420000 | E25: -615600 | F25: -4035600
B26: ORANGE - AVOIR SUR SITE MLL - TERRAFRIC /IHS_LGN_482O - NOV 22 - DEC 22 | D26: ='AVOIR TERRAFRIC décom 01 NOV 22'!L12 -> -977303.1 | E26: ='AVOIR TERRAFRIC décom 01 NOV 22'!L13 -> -175915 | F26: ='AVOIR TERRAFRIC décom 01 NOV 22'!L14 -> -1153218.1

Sheet OCI-MLL 1108 SIT Q1 -2023
F1: MLL
F2: =COUNTIF(E$17:E$1124,$F$1) -> 1108
E3: MONTHLY | F3: =SUMIF($E$17:$E$1124,"MLL",$F$17:$F$1124) -> 5.4142592e+08
E6: PU | F6: 488651.55
D12: OCI-MLL 1108 SIT Q1 - JANVIER 23 - MARS 23
F15: =SUBTOTAL(9,F17:F1124) -> 5.4142592e+08 | H15: =SUBTOTAL(9,H17:H1124) -> 1.6242778e+09 | I15: =SUBTOTAL(9,I17:I1124) -> 2.9237e+08 | J15: =SUBTOTAL(9,J17:J1124) -> 1.9166477e+09
A16: No | B16: Site ID IHS | C16: Old Site ID | D16: Site Name | E16: Category | F16: MLL | G16: MOIS | H16: TRIMESTRE HT | I16: TVA | J16: NET A PAYER Q1
A17: 1 | B17: IHS_AGN_002O | C17: ADZOPE | D17: ADZOPE | E17: MLL | F17: 488651.55 | G17: 3 | H17: =+F17*G17 -> 1465954.6 | I17: =+H17*0.18 -> 263871.84 | J17: =+H17+I17 -> 1729826.5
A18: 2 | B18: IHS_AGN_007O | C18: BIASSO | D18: BIASSO | E18: MLL | F18: 488651.55 | G18: 3 | H18: =+F18*G18 -> 1465954.6 | I18: =+H18*0.18 -> 263871.84 | J18: =+H18+I18 -> 1729826.5
A19: 3 | B19: IHS_AGN_008O | C19: MIADZIN | D19: MIADZIN | E19: MLL | F19: 488651.55 | G19: 3 | H19: =+F19*G19 -> 1465954.6 | I19: =+H19*0.18 -> 263871.84 | J19: =+H19+I19 -> 1729826.5
A20: 4 | B20: IHS_AGN_009O | C20: IRF | D20: IRF | E20: MLL | F20: 488651.55 | G20: 3 | H20: =+F20*G20 -> 1465954.6 | I20: =+H20*0.18 -> 263871.84 | J20: =+H20+I20 -> 1729826.5
A21: 5 | B21: IHS_AGN_012O | C21: MOAPE | D21: MOAPE | E21: MLL | F21: 488651.55 | G21: 3 | H21: =+F21*G21 -> 1465954.6 | I21: =+H21*0.18 -> 263871.84 | J21: =+H21+I21 -> 1729826.5
A22: 6 | B22: IHS_AGN_015M | C22: ASSIKOI | D22: ASSIKOI | E22: MLL | F22: 488651.55 | G22: 3 | H22: =+F22*G22 -> 1465954.6 | I22: =+H22*0.18 -> 263871.84 | J22: =+H22+I22 -> 1729826.5
A23: 7 | B23: IHS_AGN_017O | C23: GD_AKOUDZIN | D23: GD_AKOUDZIN | E23: MLL | F23: 488651.55 | G23: 3 | H23: =+F23*G23 -> 1465954.6 | I23: =+H23*0.18 -> 263871.84 | J23: =+H23+I23 -> 1729826.5
A24: 8 | B24: IHS_AGN_019O | C24: AGOU | D24: AGOU | E24: MLL | F24: 488651.55 | G24: 3 | H24: =+F24*G24 -> 1465954.6 | I24: =+H24*0.18 -> 263871.84 | J24: =+H24+I24 -> 1729826.5
A25: 9 | B25: IHS_AGN_020O | C25: ANANGUIE_ADZOPE | D25: ANANGUIE_ADZOPE | E25: MLL | F25: 488651.55 | G25: 3 | H25: =+F25*G25 -> 1465954.6 | I25: =+H25*0.18 -> 263871.84 | J25: =+H25+I25 -> 1729826.5
A26: 10 | B26: IHS_AGN_021O | C26: ANANGUIE | D26: ANANGUIE | E26: MLL | F26: 488651.55 | G26: 3 | H26: =+F26*G26 -> 1465954.6 | I26: =+H26*0.18 -> 263871.84 | J26: =+H26+I26 -> 1729826.5
A27: 11 | B27: IHS_AGN_023O | C27: BOUAPE | D27: BOUAPE | E27: MLL | F27: 488651.55 | G27: 3 | H27: =+F27*G27 -> 1465954.6 | I27: =+H27*0.18 -> 263871.84 | J27: =+H27+I27 -> 1729826.5
A28: 12 | B28: IHS_AGN_027O | C28: ANNEPE | D28: ANNEPE | E28: MLL | F28: 488651.55 | G28: 3 | H28: =+F28*G28 -> 1465954.6 | I28: =+H28*0.18 -> 263871.84 | J28: =+H28+I28 -> 1729826.5
... A1124: 1108 | B1124: IHS_NCE_048O | C1124: ANANDA | D1124: ANANDA | E1124: MLL | F1124: 488651.55 | G1124: 3 | H1124: =+F1124*G1124 -> 1465954.6 | I1124: =+H1124*0.18 -> 263871.84 | J1124: =+H1124+I1124 -> 1729826.5

Sheet OCI-MLL BPCI 22  SIT Q1- 2023
F1: MLL BPCI
F2: =COUNTIF(E$17:E$38,$F$1) -> 22
E3: MONTHLY | F3: =SUMIF($E$17:$E$38,"MLL BPCI",$F$17:$F$38) -> 8062747
F6: 366488.5
D11: OCI-MLL BPCI 22 SIT Q1 - JANVIER 23 - MARS 23
F15: =SUBTOTAL(9,F17:F38) -> 8062747 | H15: =SUBTOTAL(9,H17:H38) -> 24188241 | I15: =SUBTOTAL(9,I17:I38) -> 4353883.4 | J15: =SUBTOTAL(9,J17:J38) -> 28542124
A16: No | B16: Site ID IHS | C16: Old Site ID | D16: Site Name | E16: Category | F16: MLL BPCI | G16: MOIS | H16: TRIMESTRE 1 - HT | I16: TVA | J16: NET A PAYER Q1
A17: 1 | B17: IHS_AGN_055O | C17: GD_YAPO | D17: GD_YAPO | E17: MLL BPCI | F17: 366488.5 | G17: 3 | H17: =+F17*G17 -> 1099465.5 | I17: =+H17*0.18 -> 197903.79 | J17: =+H17+I17 -> 1297369.3
A18: 2 | B18: IHS_AGN_075O | C18: GOMON | D18: GOMON | E18: MLL BPCI | F18: 366488.5 | G18: 3 | H18: =+F18*G18 -> 1099465.5 | I18: =+H18*0.18 -> 197903.79 | J18: =+H18+I18 -> 1297369.3
A19: 3 | B19: IHS_BSD_130O | C19: DJESSI | D19: DJESSI | E19: MLL BPCI | F19: 366488.5 | G19: 3 | H19: =+F19*G19 -> 1099465.5 | I19: =+H19*0.18 -> 197903.79 | J19: =+H19+I19 -> 1297369.3
A20: 4 | B20: IHS_BSD_164O | C20: YACOLIDABOUO | D20: YACOLIDABOUO | E20: MLL BPCI | F20: 366488.5 | G20: 3 | H20: =+F20*G20 -> 1099465.5 | I20: =+H20*0.18 -> 197903.79 | J20: =+H20+I20 -> 1297369.3
A21: 5 | B21: IHS_BSD_168O | C21: OUREYO | D21: OUREYO | E21: MLL BPCI | F21: 366488.5 | G21: 3 | H21: =+F21*G21 -> 1099465.5 | I21: =+H21*0.18 -> 197903.79 | J21: =+H21+I21 -> 1297369.3
A22: 6 | B22: IHS_DHM_004O | C22: DOMORAUD | D22: DOMORAUD | E22: MLL BPCI | F22: 366488.5 | G22: 3 | H22: =+F22*G22 -> 1099465.5 | I22: =+H22*0.18 -> 197903.79 | J22: =+H22+I22 -> 1297369.3
A23: 7 | B23: IHS_FMG_037O | C23: ZEBIZEKOU | D23: ZEBIZEKOU | E23: MLL BPCI | F23: 366488.5 | G23: 3 | H23: =+F23*G23 -> 1099465.5 | I23: =+H23*0.18 -> 197903.79 | J23: =+H23+I23 -> 1297369.3
A24: 8 | B24: IHS_HSD_011O | C24: ESCADRON | D24: ESCADRON | E24: MLL BPCI | F24: 366488.5 | G24: 3 | H24: =+F24*G24 -> 1099465.5 | I24: =+H24*0.18 -> 197903.79 | J24: =+H24+I24 -> 1297369.3
A25: 9 | B25: IHS_HSD_012O | C25: ORLY | D25: ORLY | E25: MLL BPCI | F25: 366488.5 | G25: 3 | H25: =+F25*G25 -> 1099465.5 | I25: =+H25*0.18 -> 197903.79 | J25: =+H25+I25 -> 1297369.3
A26: 10 | B26: IHS_HSD_021O | C26: KIBOUO | D26: KIBOUO | E26: MLL BPCI | F26: 366488.5 | G26: 3 | H26: =+F26*G26 -> 1099465.5 | I26: =+H26*0.18 -> 197903.79 | J26: =+H26+I26 -> 1297369.3
A27: 11 | B27: IHS_LAC_004O | C27: CACTUS | D27: CACTUS | E27: MLL BPCI | F27: 366488.5 | G27: 3 | H27: =+F27*G27 -> 1099465.5 | I27: =+H27*0.18 -> 197903.79 | J27: =+H27+I27 -> 1297369.3
A28: 12 | B28: IHS_LGN_616O | C28: ABATA | D28: ABATA | E28: MLL BPCI | F28: 366488.5 | G28: 3 | H28: =+F28*G28 -> 1099465.5 | I28: =+H28*0.18 -> 197903.79 | J28: =+H28+I28 -> 1297369.3
... A38: 22 | B38: IHS_VDB_023O | C38: SEGUENON | D38: SEGUENON | E38: MLL BPCI | F38: 366488.5 | G38: 3 | H38: =+F38*G38 -> 1099465.5 | I38: =+H38*0.18 -> 197903.79 | J38: =+H38+I38 -> 1297369.3

Sheet OCI-MLL BPCI 18  SIT Q1 - 2023
F1: MLL BPCI
F2: =COUNTIF(E$17:E$34,$F$1) -> 18
E3: MONTHLY | F3: =SUMIF($E$17:$E$34,"MLL BPCI",$F$17:$F$34) -> 6596793
E6: PU | F6: 366488.5
D12: OCI-MLL BPCI 18 SIT Q1 - JANVIER 23 - MARS 23
F15: =SUBTOTAL(9,F17:F34) -> 6596793 | H15: =SUBTOTAL(9,H17:H34) -> 19790379 | I15: =SUBTOTAL(9,I17:I34) -> 3562268.2 | J15: =SUBTOTAL(9,J17:J34) -> 23352647
A16: No | B16: Site ID IHS | C16: Old Site ID | D16: Site Name | E16: Category | F16: MLL BPCI | G16: MOIS | H16: TRIMESTRE HT | I16: TVA | J16: NET A PAYER Q1
A17: 1 | B17: IHS_AGN_025M | C17: CI00603 | D17: Attobrou | E17: MLL BPCI | F17: 366488.5 | G17: 3 | H17: =+G17*F17 -> 1099465.5 | I17: =+H17*0.18 -> 197903.79 | J17: =+H17+I17 -> 1297369.3
A18: 2 | B18: IHS_AGN_031M | C18: CI00654 | D18: Yakasse-Attobrou | E18: MLL BPCI | F18: 366488.5 | G18: 3 | H18: =+G18*F18 -> 1099465.5 | I18: =+H18*0.18 -> 197903.79 | J18: =+H18+I18 -> 1297369.3
A19: 3 | B19: IHS_AGN_036M | C19: CI00477 | D19: BecediBrignan | E19: MLL BPCI | F19: 366488.5 | G19: 3 | H19: =+G19*F19 -> 1099465.5 | I19: =+H19*0.18 -> 197903.79 | J19: =+H19+I19 -> 1297369.3
A20: 4 | B20: IHS_AGN_041M | C20: CI00831 | D20: Akoupe | E20: MLL BPCI | F20: 366488.5 | G20: 3 | H20: =+G20*F20 -> 1099465.5 | I20: =+H20*0.18 -> 197903.79 | J20: =+H20+I20 -> 1297369.3
A21: 5 | B21: IHS_AGN_057M | C21: CI00644 | D21: Rubino | E21: MLL BPCI | F21: 366488.5 | G21: 3 | H21: =+G21*F21 -> 1099465.5 | I21: =+H21*0.18 -> 197903.79 | J21: =+H21+I21 -> 1297369.3
A22: 6 | B22: IHS_BSD_062M | C22: CI01782 | D22: Touih | E22: MLL BPCI | F22: 366488.5 | G22: 3 | H22: =+G22*F22 -> 1099465.5 | I22: =+H22*0.18 -> 197903.79 | J22: =+H22+I22 -> 1297369.3
A23: 7 | B23: IHS_DHM_034M | C23: CI00614 | D23: Mahapleu | E23: MLL BPCI | F23: 366488.5 | G23: 3 | H23: =+G23*F23 -> 1099465.5 | I23: =+H23*0.18 -> 197903.79 | J23: =+H23+I23 -> 1297369.3
A24: 8 | B24: IHS_DHM_086M | C24: CI02528 | D24: ManLycee2 | E24: MLL BPCI | F24: 366488.5 | G24: 3 | H24: =+G24*F24 -> 1099465.5 | I24: =+H24*0.18 -> 197903.79 | J24: =+H24+I24 -> 1297369.3
A25: 9 | B25: IHS_DNG_002M | C25: CI00725 | D25: OdienneAviation | E25: MLL BPCI | F25: 366488.5 | G25: 3 | H25: =+G25*F25 -> 1099465.5 | I25: =+H25*0.18 -> 197903.79 | J25: =+H25+I25 -> 1297369.3
A26: 10 | B26: IHS_FMG_059M | C26: CI00521 | D26: Dignago | E26: MLL BPCI | F26: 366488.5 | G26: 3 | H26: =+G26*F26 -> 1099465.5 | I26: =+H26*0.18 -> 197903.79 | J26: =+H26+I26 -> 1297369.3
A27: 11 | B27: IHS_LAC_002M | C27: CI00336 | D27: YakroMosquée | E27: MLL BPCI | F27: 366488.5 | G27: 3 | H27: =+G27*F27 -> 1099465.5 | I27: =+H27*0.18 -> 197903.79 | J27: =+H27+I27 -> 1297369.3
A28: 12 | B28: IHS_LGN_670M | C28: CI01191 | D28: Allokoi | E28: MLL BPCI | F28: 366488.5 | G28: 3 | H28: =+G28*F28 -> 1099465.5 | I28: =+H28*0.18 -> 197903.79 | J28: =+H28+I28 -> 1297369.3
... A34: 18 | B34: IHS_ZNZ_045M | C34: CI01025 | D34: Sandegue | E34: MLL BPCI | F34: 366488.5 | G34: 3 | H34: =+G34*F34 -> 1099465.5 | I34: =+H34*0.18 -> 197903.79 | J34: =+H34+I34 -> 1297369.3

Sheet OCI-COLOC 399 SIT Q1 - 2023
G1: COLOCATION
G2: =COUNTIF(F$16:F$414,$G$1) -> 399
F3: Monthly | G3: =SUMIF($F$16:$F$414,"COLOCATION",$G$16:$G$414) -> 5.543335e+08
E5: height | F5: Colocation
E6: Moins de 20 m | F6: 895360
E7: De 20m à 32m | F7: 1215614.7
E8: De 33m à 49m | F8: 1435883.8
E9: De 50m à 75m | F9: 1744861.9
E10: De 76m à 90m | F10: 2446709.4
E11: De 91m et 105m | F11: 2993554.6
D13: OCI-COLOC 399 SIT Q1 - JANVIER 23 - MARS 23
G14: =SUBTOTAL(9,G16:G414) -> 5.543335e+08 | I14: =SUBTOTAL(9,I16:I414) -> 1.6630005e+09 | J14: =SUBTOTAL(9,J16:J414) -> 2.9934009e+08 | K14: =SUBTOTAL(9,K16:K414) -> 1.9623406e+09
A15: No | B15: Site ID IHS | C15: Old Site ID | D15: Site Name | E15: Invoiced height | F15: Category | G15: COLOCATION | H15: MOIS | I15: TRIMESTRE HT | J15: TVA | K15: NET A PAYER Q1
A16: 1 | B16: IHS_AGN_003M | C16: CI00939 | D16: AdzopeHabitat | E16: 25 | F16: Colocation | G16: 1215614.7 | H16: 3 | I16: =+G16*H16 -> 3646844.1 | J16: =+I16*0.18 -> 656431.94 | K16: =+I16+J16 -> 4303276
A17: 2 | B17: IHS_AGN_004M | C17: CI00386 | D17: AdzopeLycee | E17: 32 | F17: Colocation | G17: 1215614.7 | H17: 3 | I17: =+G17*H17 -> 3646844.1 | J17: =+I17*0.18 -> 656431.94 | K17: =+I17+J17 -> 4303276
A18: 3 | B18: IHS_AGN_051M | C18: CI01193 | D18: Cotivo | E18: 46 | F18: Colocation | G18: 1435883.8 | H18: 3 | I18: =+G18*H18 -> 4307651.4 | J18: =+I18*0.18 -> 775377.25 | K18: =+I18+J18 -> 5083028.6
A19: 4 | B19: IHS_AGN_053M | C19: CI00940 | D19: AgbovilleSokoura | E19: 21 | F19: Colocation | G19: 1215614.7 | H19: 3 | I19: =+G19*H19 -> 3646844.1 | J19: =+I19*0.18 -> 656431.94 | K19: =+I19+J19 -> 4303276
A20: 5 | B20: IHS_AGN_056M | C20: CI01601 | D20: PetitYapo | E20: 56 | F20: Colocation | G20: 1744861.9 | H20: 3 | I20: =+G20*H20 -> 5234585.8 | J20: =+I20*0.18 -> 942225.44 | K20: =+I20+J20 -> 6176811.2
A21: 6 | B21: IHS_AGN_065M | C21: CI01535 | D21: Azaguie | E21: 49 | F21: Colocation | G21: 1435883.8 | H21: 3 | I21: =+G21*H21 -> 4307651.4 | J21: =+I21*0.18 -> 775377.25 | K21: =+I21+J21 -> 5083028.6
A22: 7 | B22: IHS_AGN_068M | C22: CI01188 | D22: Banacomoe | E22: 45 | F22: Colocation | G22: 1435883.8 | H22: 3 | I22: =+G22*H22 -> 4307651.4 | J22: =+I22*0.18 -> 775377.25 | K22: =+I22+J22 -> 5083028.6
A23: 8 | B23: IHS_AGN_086M | C23: CI01930 | D23: Otope1 | E23: 62 | F23: Colocation | G23: 1744861.9 | H23: 3 | I23: =+G23*H23 -> 5234585.8 | J23: =+I23*0.18 -> 942225.44 | K23: =+I23+J23 -> 6176811.2
A24: 9 | B24: IHS_BAF_008M | C24: CI01037 | D24: KOONAN | E24: 65 | F24: Colocation | G24: 1744861.9 | H24: 3 | I24: =+G24*H24 -> 5234585.8 | J24: =+I24*0.18 -> 942225.44 | K24: =+I24+J24 -> 6176811.2
A25: 10 | B25: IHS_BAF_009M | C25: CI01088 | D25: FOUNGBESSO | E25: 48 | F25: Colocation | G25: 1435883.8 | H25: 3 | I25: =+G25*H25 -> 4307651.4 | J25: =+I25*0.18 -> 775377.25 | K25: =+I25+J25 -> 5083028.6
A26: 11 | B26: IHS_BAF_012M | C26: CI00704 | D26: GUINTEGUELA | E26: 71 | F26: Colocation | G26: 1744861.9 | H26: 3 | I26: =+G26*H26 -> 5234585.8 | J26: =+I26*0.18 -> 942225.44 | K26: =+I26+J26 -> 6176811.2
A27: 12 | B27: IHS_BAF_014M | C27: CI01393 | D27: Kountiguisso | E27: 60 | F27: Colocation | G27: 1744861.9 | H27: 3 | I27: =+G27*H27 -> 5234585.8 | J27: =+I27*0.18 -> 942225.44 | K27: =+I27+J27 -> 6176811.2
... A414: 399 | B414: IHS_LGN_039M | C414: AdjaméRoksy | D414: AdjaméRoksy | E414: 9 | F414: Colocation | G414: 895360 | H414: 3 | I414: =+G414*H414 -> 2686080 | J414: =+I414*0.18 -> 483494.4 | K414: =+I414+J414 -> 3169574.4

Sheet OCI-PREST 193 ATHENA 1 Q1- 2023
G2: =COUNTIF(F$17:F$209,$G$1) -> 0
F3: MONTHLY | G3: =SUMIF($F$17:$F$209,"ATHENA 1",$G$17:$G$209) -> 2.4666948e+08
F5: height
F6: Moins de 20 m | G6: 805824
F7: De 20m à 32m | G7: 960335.62
F8: De 33m à 49m | G8: 1134348.2
F9: De 50m à 75m | G9: 1378440.9
F10: De 76m à 90m | G10: 1932900.4
F11: De 91m et 105m | G11: 2364908.1
D12: OCI-PREST 193 ATHENA 1 Q1 - JANVIER 23 - MARS 23
G15: =SUBTOTAL(9,G17:G209) -> 2.4666948e+08 | I15: =SUBTOTAL(9,I17:I209) -> 7.4000843e+08 | J15: =SUBTOTAL(9,J17:J209) -> 1.3320152e+08 | K15: =SUBTOTAL(9,K17:K209) -> 8.7320994e+08
A16: No | B16: Site ID IHS | C16: Old Site ID | D16: Site Name | E16: Invoiced height | F16: Category | G16: ATHENA 1 | H16: MOIS | I16: TRIMESTRE HT | J16: TVA | K16: NET A PAYER Q1
A17: 1 | B17: IHS_AGN_080M | C17: CI01899 | D17: Copa | E17: 70 | F17: ATHENA 1 | G17: 1378440.9 | H17: 3 | I17: =+G17*H17 -> 4135322.8 | J17: =+I17*0.18 -> 744358.1 | K17: =+I17+J17 -> 4879680.9
A18: 2 | B18: IHS_AGN_081M | C18: CI02034 | D18: ASSIKOUN | E18: 67 | F18: ATHENA 1 | G18: 1378440.9 | H18: 3 | I18: =+G18*H18 -> 4135322.8 | J18: =+I18*0.18 -> 744358.1 | K18: =+I18+J18 -> 4879680.9
A19: 3 | B19: IHS_AGN_082M | C19: CI02033 | D19: YAKASSEMEAZAGUIE | E19: 78.6 | F19: ATHENA 1 | G19: 1932900.4 | H19: 3 | I19: =+G19*H19 -> 5798701.3 | J19: =+I19*0.18 -> 1043766.2 | K19: =+I19+J19 -> 6842467.6
A20: 4 | B20: IHS_AGN_083M | C20: CI01928 | D20: Offoriguie | E20: 66 | F20: ATHENA 1 | G20: 1378440.9 | H20: 3 | I20: =+G20*H20 -> 4135322.8 | J20: =+I20*0.18 -> 744358.1 | K20: =+I20+J20 -> 4879680.9
A21: 5 | B21: IHS_AGN_084M | C21: CI01829 | D21: Allany | E21: 75 | F21: ATHENA 1 | G21: 1378440.9 | H21: 3 | I21: =+G21*H21 -> 4135322.8 | J21: =+I21*0.18 -> 744358.1 | K21: =+I21+J21 -> 4879680.9
A22: 6 | B22: IHS_AGN_087M | C22: CI02653 | D22: DIASSON | E22: 65 | F22: ATHENA 1 | G22: 1378440.9 | H22: 3 | I22: =+G22*H22 -> 4135322.8 | J22: =+I22*0.18 -> 744358.1 | K22: =+I22+J22 -> 4879680.9
A23: 7 | B23: IHS_BAF_027M | C23: CI02610 | D23: GOUANA | E23: 78 | F23: ATHENA 1 | G23: 1932900.4 | H23: 3 | I23: =+G23*H23 -> 5798701.3 | J23: =+I23*0.18 -> 1043766.2 | K23: =+I23+J23 -> 6842467.6
A24: 8 | B24: IHS_BAF_028M | C24: CI02611 | D24: N'GOLODOUGOU | E24: 48 | F24: ATHENA 1 | G24: 1134348.2 | H24: 3 | I24: =+G24*H24 -> 3403044.6 | J24: =+I24*0.18 -> 612548.02 | K24: =+I24+J24 -> 4015592.6
A25: 9 | B25: IHS_BAF_029M | C25: CI02612 | D25: TOURESSO 2 | E25: 48 | F25: ATHENA 1 | G25: 1134348.2 | H25: 3 | I25: =+G25*H25 -> 3403044.6 | J25: =+I25*0.18 -> 612548.02 | K25: =+I25+J25 -> 4015592.6
A26: 10 | B26: IHS_BAF_030M | C26: CI02609 | D26: BOUINDALA | E26: 78 | F26: ATHENA 1 | G26: 1932900.4 | H26: 3 | I26: =+G26*H26 -> 5798701.3 | J26: =+I26*0.18 -> 1043766.2 | K26: =+I26+J26 -> 6842467.6
A27: 11 | B27: IHS_BSD_201M | C27: CI02041 | D27: PETITGABO | E27: 76 | F27: ATHENA 1 | G27: 1932900.4 | H27: 3 | I27: =+G27*H27 -> 5798701.3 | J27: =+I27*0.18 -> 1043766.2 | K27: =+I27+J27 -> 6842467.6
A28: 12 | B28: IHS_BSD_202M | C28: CI02038 | D28: MAPRI | E28: 77 | F28: ATHENA 1 | G28: 1932900.4 | H28: 3 | I28: =+G28*H28 -> 5798701.3 | J28: =+I28*0.18 -> 1043766.2 | K28: =+I28+J28 -> 6842467.6
... A209: 193 | B209: IHS_ZNZ_091M | C209: CI02711 | D209: POKO | E209: 68 | F209: ATHENA 1 | G209: 1378440.9 | H209: 3 | I209: =+G209*H209 -> 4135322.8 | J209: =+I209*0.18 -> 744358.1 | K209: =+I209+J209 -> 4879680.9

Sheet OCI-ATHENA 2-125 SIT Q1- 2023
H1: ATHENA 2
E2: Données mois N | H2: =COUNTIF(G$17:G$141,$H$1) -> 125
H3: =SUMIF($G$17:$G$141,"ATHENA 2",$H$17:$H$141) -> 1.3688431e+08
G5: height
G6: ORANGE | H6: Athena 2
G7: gestion existant | H7: 0.18
G8: De moins de 20m | H8: 734195.2
G9: De 20m à 32m | H9: 996804.06
G10: De 33m à 49m | H10: 1177424.7
G11: De 50m à 75m | H11: 1430786.8
G12: De 76m à 90m | H12: 2006301.7
E13: OCI-ATHENA 2 -125 SIT Q1 - JANVIER 23 - MARS 23 | G13: De 91m à 105m | H13: 2454714.8
H15: =SUBTOTAL(9,H17:H141) -> 1.3688431e+08 | J15: =SUBTOTAL(9,J17:J141) -> 4.1065293e+08 | K15: =SUBTOTAL(9,K17:K141) -> 73917527 | L15: =SUBTOTAL(9,L17:L141) -> 4.8457045e+08
A16: No | B16: Site ID IHS | D16: Old Site ID | E16: Site Name | F16: Invoiced height | G16: Category | H16: ATHENA 2 | I16: MOIS | J16: TRIMESTRE HT | K16: TVA | L16: NET A PAYER Q1
A17: 1 | B17: IHS_AGN_090M | C17: Adzope2018 | D17: CI02919 | E17: Adzope2018 | F17: 26.5 | G17: ATHENA 2 | H17: 996804.06 | I17: 3 | J17: =+H17*I17 -> 2990412.2 | K17: =+J17*0.18 -> 538274.19 | L17: =+J17+K17 -> 3528686.4
A18: 2 | B18: IHS_AGN_091M | C18: ADZOPEMARCHE | E18: ADZOPEMARCHE | F18: 27 | G18: ATHENA 2 | H18: 996804.06 | I18: 3 | J18: =+H18*I18 -> 2990412.2 | K18: =+J18*0.18 -> 538274.19 | L18: =+J18+K18 -> 3528686.4
A19: 3 | B19: IHS_AGN_092M | C19: AdzopeRoad | D19: CI03138 | E19: AdzopeRoad | F19: 50 | G19: ATHENA 2 | H19: 1430786.8 | I19: 3 | J19: =+H19*I19 -> 4292360.3 | K19: =+J19*0.18 -> 772624.86 | L19: =+J19+K19 -> 5064985.2
A20: 4 | B20: IHS_BSD_016M | C20: ROUTE_BEREBY | E20: ROUTE_BEREBY | F20: 13 | G20: ATHENA 2 | H20: 734195.2 | I20: 3 | J20: =+H20*I20 -> 2202585.6 | K20: =+J20*0.18 -> 396465.41 | L20: =+J20+K20 -> 2599051
A21: 5 | B21: IHS_BSD_228M | C21: SANPEDRONITORO2 | E21: SANPEDRONITORO2 | F21: 52 | G21: ATHENA 2 | H21: 1430786.8 | I21: 3 | J21: =+H21*I21 -> 4292360.3 | K21: =+J21*0.18 -> 772624.86 | L21: =+J21+K21 -> 5064985.2
A22: 6 | B22: IHS_BSD_231M | C22: MeaguiNorth | D22: CI03137 | E22: MeaguiNorth | F22: 35 | G22: ATHENA 2 | H22: 1177424.7 | I22: 3 | J22: =+H22*I22 -> 3532274.1 | K22: =+J22*0.18 -> 635809.34 | L22: =+J22+K22 -> 4168083.4
A23: 7 | B23: IHS_BSD_232M | C23: MeaguiSouth | D23: CI03136 | E23: MeaguiSouth | F23: 29 | G23: ATHENA 2 | H23: 996804.06 | I23: 3 | J23: =+H23*I23 -> 2990412.2 | K23: =+J23*0.18 -> 538274.19 | L23: =+J23+K23 -> 3528686.4
A24: 8 | B24: IHS_BSD_233M | C24: SoubreGabonExt | D24: CI03167 | E24: SoubreGabonExt | F24: 31 | G24: ATHENA 2 | H24: 996804.06 | I24: 3 | J24: =+H24*I24 -> 2990412.2 | K24: =+J24*0.18 -> 538274.19 | L24: =+J24+K24 -> 3528686.4
A25: 9 | B25: IHS_BSD_234M | C25: SoubreGabonExt1 | D25: CI03168 | E25: SoubreGabonExt1 | F25: 34 | G25: ATHENA 2 | H25: 1177424.7 | I25: 3 | J25: =+H25*I25 -> 3532274.1 | K25: =+J25*0.18 -> 635809.34 | L25: =+J25+K25 -> 4168083.4
A26: 10 | B26: IHS_BSD_243M | C26: SAN-PEDRO_New2 | D26: CI03154 | E26: SAN-PEDRO_New2 | F26: 30 | G26: ATHENA 2 | H26: 996804.06 | I26: 3 | J26: =+H26*I26 -> 2990412.2 | K26: =+J26*0.18 -> 538274.19 | L26: =+J26+K26 -> 3528686.4
A27: 11 | B27: IHS_BSD_245M | C27: SAN-PEDRO_NEW4 | E27: SAN-PEDRO_NEW4 | F27: 28 | G27: ATHENA 2 | H27: 996804.06 | I27: 3 | J27: =+H27*I27 -> 2990412.2 | K27: =+J27*0.18 -> 538274.19 | L27: =+J27+K27 -> 3528686.4
A28: 12 | B28: IHS_BSD_246M | C28: SanPedroPoro | D28: CI03155 | E28: SanPedroPoro | F28: 29 | G28: ATHENA 2 | H28: 996804.06 | I28: 3 | J28: =+H28*I28 -> 2990412.2 | K28: =+J28*0.18 -> 538274.19 | L28: =+J28+K28 -> 3528686.4
A29: 13 | B29: IHS_BSD_247M | C29: SanPedroRteBereby | D29: CI03158 | E29: SanPedroRteBereby | F29: 42 | G29: ATHENA 2 | H29: 1177424.7 | I29: 3 | J29: =+H29*I29 -> 3532274.1 | K29: =+J29*0.18 -> 635809.34 | L29: =+J29+K29 -> 4168083.4
A30: 14 | B30: IHS_DHM_105M | C30: MAN_New2 | D30: CI03133 | E30: MAN_New2 | F30: 27 | G30: ATHENA 2 | H30: 996804.06 | I30: 3 | J30: =+H30*I30 -> 2990412.2 | K30: =+J30*0.18 -> 538274.19 | L30: =+J30+K30 -> 3528686.4
A31: 15 | B31: IHS_DHM_107M | C31: ManOuest | D31: CI03134 | E31: ManOuest | F31: 29 | G31: ATHENA 2 | H31: 996804.06 | I31: 3 | J31: =+H31*I31 -> 2990412.2 | K31: =+J31*0.18 -> 538274.19 | L31: =+J31+K31 -> 3528686.4
A32: 16 | B32: IHS_DHM_108M | C32: ManRenfo | D32: CI03135 | E32: ManRenfo | F32: 40 | G32: ATHENA 2 | H32: 1177424.7 | I32: 3 | J32: =+H32*I32 -> 3532274.1 | K32: =+J32*0.18 -> 635809.34 | L32: =+J32+K32 -> 4168083.4
A33: 17 | B33: IHS_DNG_052M | C33: ODIENNE1 | E33: ODIENNE1 | F33: 30 | G33: ATHENA 2 | H33: 996804.06 | I33: 3 | J33: =+H33*I33 -> 2990412.2 | K33: =+J33*0.18 -> 538274.19 | L33: =+J33+K33 -> 3528686.4
A34: 18 | B34: IHS_DNG_053M | C34: OdienneLyceeModerne | D34: CI03144 | E34: OdienneLyceeModerne | F34: 30 | G34: ATHENA 2 | H34: 996804.06 | I34: 3 | J34: =+H34*I34 -> 2990412.2 | K34: =+J34*0.18 -> 538274.19 | L34: =+J34+K34 -> 3528686.4
A35: 19 | B35: IHS_DNG_054M | C35: OdienneRteAeroport | D35: CI02529 | E35: OdienneRteAeroport | F35: 29 | G35: ATHENA 2 | H35: 996804.06 | I35: 3 | J35: =+H35*I35 -> 2990412.2 | K35: =+J35*0.18 -> 538274.19 | L35: =+J35+K35 -> 3528686.4
A36: 20 | B36: IHS_FMG_106M | C36: GAGNOA_New1 | D36: CI03107 | E36: GAGNOA_New1 | F36: 35 | G36: ATHENA 2 | H36: 1177424.7 | I36: 3 | J36: =+H36*I36 -> 3532274.1 | K36: =+J36*0.18 -> 635809.34 | L36: =+J36+K36 -> 4168083.4
A37: 21 | B37: IHS_FMG_107M | C37: GAGNOA_New2 | D37: CI03105 | E37: GAGNOA_New2 | F37: 34 | G37: ATHENA 2 | H37: 1177424.7 | I37: 3 | J37: =+H37*I37 -> 3532274.1 | K37: =+J37*0.18 -> 635809.34 | L37: =+J37+K37 -> 4168083.4
A38: 22 | B38: IHS_FMG_108M | C38: GAGNOA_New3 | D38: CI03106 | E38: GAGNOA_New3 | F38: 28 | G38: ATHENA 2 | H38: 996804.06 | I38: 3 | J38: =+H38*I38 -> 2990412.2 | K38: =+J38*0.18 -> 538274.19 | L38: =+J38+K38 -> 3528686.4
A39: 23 | B39: IHS_FMG_109M | C39: GagnoaRteLakota | D39: CI03108 | E39: GagnoaRteLakota | F39: 29 | G39: ATHENA 2 | H39: 996804.06 | I39: 3 | J39: =+H39*I39 -> 2990412.2 | K39: =+J39*0.18 -> 538274.19 | L39: =+J39+K39 -> 3528686.4
A40: 24 | B40: IHS_HSD_004M | C40: DaloaFadiga | E40: DaloaFadiga | F40: 25 | G40: ATHENA 2 | H40: 996804.06 | I40: 3 | J40: =+H40*I40 -> 2990412.2 | K40: =+J40*0.18 -> 538274.19 | L40: =+J40+K40 -> 3528686.4
A41: 25 | B41: IHS_HSD_009M | C41: Daloa Abattoir_New | E41: Daloa Abattoir_New | F41: 24 | G41: ATHENA 2 | H41: 996804.06 | I41: 3 | J41: =+H41*I41 -> 2990412.2 | K41: =+J41*0.18 -> 538274.19 | L41: =+J41+K41 -> 3528686.4
A42: 26 | B42: IHS_HSD_143M | C42: DaloaMarché | D42: CI03084 | E42: DaloaMarché | F42: 47 | G42: ATHENA 2 | H42: 1177424.7 | I42: 3 | J42: =+H42*I42 -> 3532274.1 | K42: =+J42*0.18 -> 635809.34 | L42: =+J42+K42 -> 4168083.4
...

Sheet OCI-BTS 150 SIT Q1 - 2023
G1: BTS
G2: =COUNTIF(F$17:F$166,$G$1) -> 150
F3: MONTHLY | G3: H
F5: height
F6: Moins de 20 m | G6: 895360
F7: De 20m à 32m | G7: 1215614.7
F8: De 33m à 49m | G8: 1435883.8
F9: De 50m à 75m | G9: 1744861.9
F10: De 76m à 90m | G10: 2446709.4
F11: De 91m et 105m + | G11: 2993554.6
D13: OCI-BTS 150 SIT Q1 - JANVIER 23 - MARS 23
G15: =SUBTOTAL(9,G17:G166) -> 2.2900477e+08 | I15: =SUBTOTAL(9,I17:I166) -> 6.8701432e+08 | J15: =SUBTOTAL(9,J17:J166) -> 1.2366258e+08 | K15: =SUBTOTAL(9,K17:K166) -> 8.106769e+08
A16: No | B16: Site ID IHS | C16: Old Site ID | D16: Site Name | E16: Invoiced height | F16: Category | G16: =G1 -> BTS | H16: MOIS | I16: TRIMESTRE HT | J16: TVA | K16: NET A PAYER Q1
A17: 1 | B17: IHS_AGN_085O | C17: ANNO | D17: ANNO | E17: 60 | F17: BTS | G17: 1744861.9 | H17: 3 | I17: =+G17*H17 -> 5234585.8 | J17: =+I17*0.18 -> 942225.44 | K17: =+I17+J17 -> 6176811.2
A18: 2 | B18: IHS_AGN_088O | C18: ADZOPE_CORRIDOR | D18: ADZOPE_CORRIDOR | E18: 42 | F18: BTS | G18: 1435883.8 | H18: 3 | I18: =+G18*H18 -> 4307651.4 | J18: =+I18*0.18 -> 775377.25 | K18: =+I18+J18 -> 5083028.6
A19: 3 | B19: IHS_AGN_089O | C19: KODIEBOUMA | D19: KODIEBOUMA | E19: 79 | F19: BTS | G19: 2446709.4 | H19: 3 | I19: =+G19*H19 -> 7340128.3 | J19: =+I19*0.18 -> 1321223.1 | K19: =+I19+J19 -> 8661351.4
A20: 4 | B20: IHS_BAF_025O | C20: SABOUDOUGOU | D20: SABOUDOUGOU | E20: 83 | F20: BTS | G20: 2446709.4 | H20: 3 | I20: =+G20*H20 -> 7340128.3 | J20: =+I20*0.18 -> 1321223.1 | K20: =+I20+J20 -> 8661351.4
A21: 5 | B21: IHS_BSD_204O | C21: NV SASSANDRA | D21: NV SASSANDRA | E21: 54 | F21: BTS | G21: 1744861.9 | H21: 3 | I21: =+G21*H21 -> 5234585.8 | J21: =+I21*0.18 -> 942225.44 | K21: =+I21+J21 -> 6176811.2
A22: 6 | B22: IHS_BSD_205O | C22: GRIHIRI | D22: GRIHIRI | E22: 62 | F22: BTS | G22: 1744861.9 | H22: 3 | I22: =+G22*H22 -> 5234585.8 | J22: =+I22*0.18 -> 942225.44 | K22: =+I22+J22 -> 6176811.2
A23: 7 | B23: IHS_BSD_209O | C23: KAKO VILLAGE | D23: KAKO VILLAGE | E23: 62 | F23: BTS | G23: 1744861.9 | H23: 3 | I23: =+G23*H23 -> 5234585.8 | J23: =+I23*0.18 -> 942225.44 | K23: =+I23+J23 -> 6176811.2
A24: 8 | B24: IHS_BSD_210O | C24: POLLET | D24: POLLET | E24: 55 | F24: BTS | G24: 1744861.9 | H24: 3 | I24: =+G24*H24 -> 5234585.8 | J24: =+I24*0.18 -> 942225.44 | K24: =+I24+J24 -> 6176811.2
A25: 9 | B25: IHS_BSD_211O | C25: SOUBRE_RIVER | D25: SOUBRE_RIVER | E25: 52 | F25: BTS | G25: 1744861.9 | H25: 3 | I25: =+G25*H25 -> 5234585.8 | J25: =+I25*0.18 -> 942225.44 | K25: =+I25+J25 -> 6176811.2
A26: 10 | B26: IHS_BSD_218O | C26: GAROUBRE | D26: GAROUBRE | E26: 78 | F26: BTS | G26: 2446709.4 | H26: 3 | I26: =+G26*H26 -> 7340128.3 | J26: =+I26*0.18 -> 1321223.1 | K26: =+I26+J26 -> 8661351.4
A27: 11 | B27: IHS_BSD_219O | C27: SP_BELLEVILLE | D27: SP_BELLEVILLE | E27: 40 | F27: BTS | G27: 1435883.8 | H27: 3 | I27: =+G27*H27 -> 4307651.4 | J27: =+I27*0.18 -> 775377.25 | K27: =+I27+J27 -> 5083028.6
A28: 12 | B28: IHS_BSD_220O | C28: PETIT_BOUAKE | D28: PETIT_BOUAKE | E28: 69 | F28: BTS | G28: 1744861.9 | H28: 3 | I28: =+G28*H28 -> 5234585.8 | J28: =+I28*0.18 -> 942225.44 | K28: =+I28+J28 -> 6176811.2
... A166: 150 | B166: IHS_ZNZ_094O | C166: DJORO-DJORO | D166: DJORO-DJORO | E166: 71 | F166: BTS | G166: 1744861.9 | H166: 3 | I166: =+G166*H166 -> 5234585.8 | J166: =+I166*0.18 -> 942225.44 | K166: =+I166+J166 -> 6176811.2

Sheet OCI-65 SIT  BARTER Q1 - 2023
G1: BARTER
G2: =COUNTIF(F$17:F$81,$G$1) -> 65
F3: MONTHLY | G3: =SUMIF($F$17:$F$81,"BARTER",$G$17:$G$81) -> 92355143
F5: height
F6: Moins de 20 m | G6: 805824
F7: De 20m à 32m | G7: 1094053.2
F8: De 33m à 49m | G8: 1292295.4
F9: De 50m à 75m | G9: 1570375.7
F10: De 76m à 90m | G10: 2202038.5
F11: De 91m à 105m + | G11: 2694199.1
D13: OCI-65 SIT BARTER Q1 - JANVIER 23 - MARS 23
G15: =SUBTOTAL(9,G17:G81) -> 92355143 | I15: =SUBTOTAL(9,I17:I81) -> 2.7706543e+08 | J15: =SUBTOTAL(9,J17:J81) -> 49871777 | K15: =SUBTOTAL(9,K17:K81) -> 3.2693721e+08
A16: No | B16: Site ID IHS | C16: Old Site ID | D16: Site Name | E16: Invoiced height | F16: Category | G16: BARTER | H16: MOIS | I16: TRIMESTRE HT | J16: TVA | K16: NET A PAYER Q1
A17: 1 | B17: IHS_AGN_044M | C17: CI01077 | D17: Abongoua | E17: 62 | F17: BARTER | G17: 1570375.7 | H17: 3 | I17: =+G17*H17 -> 4711127.2 | J17: =+I17*0.18 -> 848002.89 | K17: =+I17+J17 -> 5559130.1
A18: 2 | B18: IHS_AGN_066M | C18: CI00737 | D18: Guessiguie | E18: 60 | F18: BARTER | G18: 1570375.7 | H18: 3 | I18: =+G18*H18 -> 4711127.2 | J18: =+I18*0.18 -> 848002.89 | K18: =+I18+J18 -> 5559130.1
A19: 3 | B19: IHS_BSD_020M | C19: CI01475 | D19: SanPedroNitro | E19: 32 | F19: BARTER | G19: 1094053.2 | H19: 3 | I19: =+G19*H19 -> 3282159.7 | J19: =+I19*0.18 -> 590788.75 | K19: =+I19+J19 -> 3872948.5
A20: 4 | B20: IHS_BSD_026M | C20: CI00501 | D20: Blahou | E20: 69 | F20: BARTER | G20: 1570375.7 | H20: 3 | I20: =+G20*H20 -> 4711127.2 | J20: =+I20*0.18 -> 848002.89 | K20: =+I20+J20 -> 5559130.1
A21: 5 | B21: IHS_BSD_085M | C21: CI00564 | D21: Progreagui | E21: 60 | F21: BARTER | G21: 1570375.7 | H21: 3 | I21: =+G21*H21 -> 4711127.2 | J21: =+I21*0.18 -> 848002.89 | K21: =+I21+J21 -> 5559130.1
A22: 6 | B22: IHS_DHM_012M | C22: CI00590 | D22: Nidrou | E22: 58 | F22: BARTER | G22: 1570375.7 | H22: 3 | I22: =+G22*H22 -> 4711127.2 | J22: =+I22*0.18 -> 848002.89 | K22: =+I22+J22 -> 5559130.1
A23: 7 | B23: IHS_DHM_013M | C23: CI00699 | D23: Facobly | E23: 54 | F23: BARTER | G23: 1570375.7 | H23: 3 | I23: =+G23*H23 -> 4711127.2 | J23: =+I23*0.18 -> 848002.89 | K23: =+I23+J23 -> 5559130.1
A24: 8 | B24: IHS_DHM_017M | C24: CI00627 | D24: SANGOUINE | E24: 60 | F24: BARTER | G24: 1570375.7 | H24: 3 | I24: =+G24*H24 -> 4711127.2 | J24: =+I24*0.18 -> 848002.89 | K24: =+I24+J24 -> 5559130.1
A25: 9 | B25: IHS_DHM_049M | C25: CI00693 | D25: Banteadepleu | E25: 56 | F25: BARTER | G25: 1570375.7 | H25: 3 | I25: =+G25*H25 -> 4711127.2 | J25: =+I25*0.18 -> 848002.89 | K25: =+I25+J25 -> 5559130.1
A26: 10 | B26: IHS_FMG_062M | C26: CI00765 | D26: Bahompa | E26: 58 | F26: BARTER | G26: 1570375.7 | H26: 3 | I26: =+G26*H26 -> 4711127.2 | J26: =+I26*0.18 -> 848002.89 | K26: =+I26+J26 -> 5559130.1
A27: 11 | B27: IHS_FMG_074M | C27: CI01095 | D27: Equigold | E27: 39 | F27: BARTER | G27: 1292295.4 | H27: 3 | I27: =+G27*H27 -> 3876886.2 | J27: =+I27*0.18 -> 697839.52 | K27: =+I27+J27 -> 4574725.8
A28: 12 | B28: IHS_HSD_023M | C28: CI01073 | D28: Tahiraguhé | E28: 45 | F28: BARTER | G28: 1292295.4 | H28: 3 | I28: =+G28*H28 -> 3876886.2 | J28: =+I28*0.18 -> 697839.52 | K28: =+I28+J28 -> 4574725.8
... A81: 65 | B81: IHS_ZNZ_057M | C81: CI01027 | D81: Yorobodi | E81: 44 | F81: BARTER | G81: 1292295.4 | H81: 3 | I81: =+G81*H81 -> 3876886.2 | J81: =+I81*0.18 -> 697839.52 | K81: =+I81+J81 -> 4574725.8

Sheet OCI-33 SITES TIERS JANVIER  23
F1: 33 SITES TIERS
F2: =COUNTIF(E$17:E$49,$F$1) -> 33
E3: MONTHLY | F3: =SUMIF($E$17:$E$49,"33 SITES TIERS",$F$17:$F$49) -> 38963846
E6: PU | F6: 1180722.6
D13: OCI-33 SITES TIERS - JANVIER 23
F15: =SUBTOTAL(9,F17:F49) -> 38963846 | G15: =SUBTOTAL(9,G17:G49) -> 7013492.2 | H15: =SUBTOTAL(9,H17:H49) -> 45977338
A16: No | B16: Site ID IHS | C16: Old Site ID | D16: Site Name | E16: Category | F16: 33 SITES TIERS | G16: TVA | H16: NET A PAYER
A17: 1 | B17: CI05850 | C17: WOUKOLO | D17: WOUKOLO | E17: 33 SITES TIERS | F17: 1180722.6 | G17: 212530.07 | H17: 1393252.7
A18: 2 | B18: CI09000 | C18: AHEREMOU_ADJEKRO | D18: AHEREMOU_ADJEKRO | E18: 33 SITES TIERS | F18: 1180722.6 | G18: 212530.07 | H18: 1393252.7
A19: 3 | B19: CI09002 | C19: AKOVIEBO | D19: AKOVIEBO | E19: 33 SITES TIERS | F19: 1180722.6 | G19: 212530.07 | H19: 1393252.7
A20: 4 | B20: CI09003 | C20: AMICA | D20: AMICA | E20: 33 SITES TIERS | F20: 1180722.6 | G20: 212530.07 | H20: 1393252.7
A21: 5 | B21: CI09004 | C21: BASILIQUE | D21: BASILIQUE | E21: 33 SITES TIERS | F21: 1180722.6 | G21: 212530.07 | H21: 1393252.7
A22: 6 | B22: CI09005 | C22: BEGNERI | D22: BEGNERI | E22: 33 SITES TIERS | F22: 1180722.6 | G22: 212530.07 | H22: 1393252.7
A23: 7 | B23: CI09007 | C23: CANAAN | D23: CANAAN | E23: 33 SITES TIERS | F23: 1180722.6 | G23: 212530.07 | H23: 1393252.7
A24: 8 | B24: CI09008 | C24: CENTRALE_AZ | D24: CENTRALE_AZ | E24: 33 SITES TIERS | F24: 1180722.6 | G24: 212530.07 | H24: 1393252.7
A25: 9 | B25: CI09010 | C25: ENI | D25: ENI | E25: 33 SITES TIERS | F25: 1180722.6 | G25: 212530.07 | H25: 1393252.7
A26: 10 | B26: CI09011 | C26: ENSTP | D26: ENSTP | E26: 33 SITES TIERS | F26: 1180722.6 | G26: 212530.07 | H26: 1393252.7
A27: 11 | B27: CI09013 | C27: FISHANDMEAT | D27: FISHANDMEAT | E27: 33 SITES TIERS | F27: 1180722.6 | G27: 212530.07 | H27: 1393252.7
A28: 12 | B28: CI09014 | C28: FONDATION | D28: FONDATION | E28: 33 SITES TIERS | F28: 1180722.6 | G28: 212530.07 | H28: 1393252.7
... A49: 33 | B49: IHS_LGN_678O | C49: SONGON MAIRIE | D49: SONGON MAIRIE | E49: 33 SITES TIERS | F49: 1180722.6 | G49: 212530.07 | H49: 1393252.7

Sheet AVOIR 18 SIT LOYER BARTER Q1-23
A3: N° | B3: CODE SITE IHS | C3: CODE SITE CLIENT | D3: DESCRIPTION | I3: PRIX UNITAIRE (Fcfa) | J3: QUANTITE (mois) | K3: TOTAL (Fcfa)
D5: Régularisation Avoir sur Loyers réduits 18 sites existants - ex Barter / Q4 - 22
A8: 1 | B8: IHS_BSD_026M | C8: CI00501 | D8: BLAHOU | F8: 69 | G8: 44927 | H8: 45016 | I8: 90000 | J8: 3 | K8: =+I8*J8 -> 270000
A9: 2 | B9: IHS_LAC_084M | C9: CI00508 | D9: KPOUEBO | F9: 65 | G9: 44927 | H9: 45016 | I9: 90000 | J9: 3 | K9: =+I9*J9 -> 270000
A10: 3 | B10: IHS_VDB_066M | C10: CI00687 | D10: ANDOKREKRENOU | F10: 58 | G10: 44927 | H10: 45016 | I10: 60000 | J10: 3 | K10: =+I10*J10 -> 180000
A11: 4 | B11: IHS_DHM_049M | C11: CI00693 | D11: ZIANSIEUPLEU | F11: 56 | G11: 44927 | H11: 45016 | I11: 60000 | J11: 3 | K11: =+I11*J11 -> 180000
A12: 5 | B12: IHS_NCE_015M | C12: CI00739 | D12: BENGASSOU | F12: 60 | G12: 44927 | H12: 45016 | I12: 60000 | J12: 3 | K12: =+I12*J12 -> 180000
A13: 6 | B13: IHS_NCE_039M | C13: CI00744 | D13: NZECREZESSOU | F13: 57 | G13: 44927 | H13: 45016 | I13: 60000 | J13: 3 | K13: =+I13*J13 -> 180000
A14: 7 | B14: IHS_LGN_729M | C14: CI00752 | D14: DINGUIRA | F14: 58 | G14: 44927 | H14: 45016 | I14: 60000 | J14: 3 | K14: =+I14*J14 -> 180000
A15: 8 | B15: IHS_ZNZ_038M | C15: CI01008 | D15: NAMASSI | F15: 46 | G15: 44927 | H15: 45016 | I15: 60000 | J15: 3 | K15: =+I15*J15 -> 180000
A16: 9 | B16: IHS_HSD_023M | C16: CI01073 | D16: TAHIRAGUHE | F16: 45 | G16: 44927 | H16: 45016 | I16: 60000 | J16: 3 | K16: =+I16*J16 -> 180000
A17: 10 | B17: IHS_AGN_044M | C17: CI01077 | D17: ABONGOUA_ATTOBROU | F17: 62 | G17: 44927 | H17: 45016 | I17: 60000 | J17: 3 | K17: =+I17*J17 -> 180000
A18: 11 | B18: IHS_DHM_012M | C18: CI00590 | D18: NIDROU | F18: 58 | G18: 44927 | H18: 45016 | I18: 60000 | J18: 3 | K18: =+I18*J18 -> 180000
A19: 12 | B19: IHS_VDB_068M | C19: CI00691 | D19: TOUMODI_SAKASSOU | F19: 61 | G19: 44927 | H19: 45016 | I19: 60000 | J19: 3 | K19: =+I19*J19 -> 180000
... A25: 18 | B25: IHS_WRD_025M | C25: CI01152 | D25: FADIADOUGOU | F25: 55 | G25: 44927 | H25: 45016 | I25: 60000 | J25: 3 | K25: =+I25*J25 -> 180000
I27: TOTAL HT | K27: =IF(SUM(K4:K26)>0,SUM(K4:K26),"") -> 3420000
I28: TVA | J28: 0.18 | K28: =IF(K27<>"",ROUND(K27*18%,0),"") -> 615600
I29: TOTAL TTC | K29: =IF(K27<>"",SUM(K27:K28),"") -> 4035600

Sheet PROV 18 Sites Coloc Nawa  22-23
B5: PV OCI PROJET 18 SITES COLOCATION NAWA ( en attente du contrat signé pour facturation ) | N5: 0.15 | O5: Provisions
B6: S/N | C6: MOIS | D6: CODE IHS | E6: NOM DU SITE | F6: DESCRIPTION | G6: DATE DE DEBUT | H6: DATE DE FIN | I6: MOIS | J6: MOIS (Two decimals) | K6: HAUTEUR | L6: PU | M6: TOTAL | N6: 15% Discount | O6: MONTANT | P6: PERIODE
B7: 1 | C7: PROV ORANGE-COLOC NAWA - Site TIEZANKRO 3 - AVR 22 | D7: IHS_LAC_124O | E7: TIEZANKRO 3 | F7: Colocation -15% Discount | G7: 44666 | H7: 44681 | I7: =((H7-G7)+1)/30 -> 0.53333333 | J7: =ROUND(I7,2) -> 0.53 | K7: 65 | L7: 1744861.9 | M7: =L7*J7 -> 924776.82 | N7: =M7*$N$5 -> 138716.52 | O7: =M7-N7 -> 786060.3 | P7: 44652
B8: 2 | C8: PROV ORANGE-COLOC NAWA - Site Blolequin New - AVR 22 | D8: IHS_WRD_004M | E8: Blolequin New | F8: Colocation -15% Discount | G8: 44670 | H8: 44681 | I8: =((H8-G8)+1)/30 -> 0.4 | J8: =ROUND(I8,2) -> 0.4 | K8: 60 | L8: 1744861.9 | M8: =L8*J8 -> 697944.77 | N8: =M8*$N$5 -> 104691.72 | O8: =M8-N8 -> 593253.06 | P8: 44652
B9: 3 | C9: PROV ORANGE-COLOC NAWA - Site ZAGUIETA - AVR 22 | D9: IHS_MRH_081M | E9: ZAGUIETA | F9: Colocation -15% Discount | G9: 44668 | H9: 44681 | I9: =((H9-G9)+1)/30 -> 0.46666667 | J9: =ROUND(I9,2) -> 0.47 | K9: 54 | L9: 1744861.9 | M9: =L9*J9 -> 820085.11 | N9: =M9*$N$5 -> 123012.77 | O9: =M9-N9 -> 697072.34 | P9: 44652
B10: 4 | C10: PROV ORANGE-COLOC NAWA - BROUSSOUPALEGNOA - AVR 22 | D10: IHS_SBD_099M | E10: BROUSSOUPALEGNOA | F10: Colocation -15% Discount | G10: 44672 | H10: 44681 | I10: =((H10-G10)+1)/30 -> 0.33333333 | J10: =ROUND(I10,2) -> 0.33 | K10: 65 | L10: 1744861.9 | M10: =L10*J10 -> 575804.44 | N10: =M10*$N$5 -> 86370.665 | O10: =M10-N10 -> 489433.77 | P10: 44652
B11: 5 | C11: PROV ORANGE-COLOC NAWA - M'bahiakro2 - AVR 22 | D11: IHS_NCE_057M | E11: M'bahiakro2 | F11: Colocation -15% Discount | G11: 44667 | H11: 44681 | I11: =((H11-G11)+1)/30 -> 0.5 | J11: =ROUND(I11,2) -> 0.5 | K11: 45 | L11: 1435883.8 | M11: =L11*J11 -> 717941.89 | N11: =M11*$N$5 -> 107691.28 | O11: =M11-N11 -> 610250.61 | P11: 44652
B12: 6 | C12: PROV ORANGE-COLOC NAWA - AYENOUAN - AVR 22 | D12: IHS_SCE_108M | E12: AYENOUAN | F12: Colocation -15% Discount | G12: 44664 | H12: 44681 | I12: =((H12-G12)+1)/30 -> 0.6 | J12: =ROUND(I12,2) -> 0.6 | K12: 50 | L12: 1744861.9 | M12: =L12*J12 -> 1046917.2 | N12: =M12*$N$5 -> 157037.57 | O12: =M12-N12 -> 889879.58 | P12: 44652
B13: 7 | C13: PROV ORANGE-COLOC NAWA - GuitryMTN - AVR 22 | D13: IHS_SBD_050M | E13: GuitryMTN | F13: Colocation -15% Discount | G13: 44665 | H13: 44681 | I13: =((H13-G13)+1)/30 -> 0.56666667 | J13: =ROUND(I13,2) -> 0.57 | K13: 42 | L13: 1435883.8 | M13: =L13*J13 -> 818453.76 | N13: =M13*$N$5 -> 122768.06 | O13: =M13-N13 -> 695685.7 | P13: 44652
B14: 8 | C14: PROV ORANGE-COLOC NAWA - Site TIEZANKRO 3 - MAI 22 | D14: IHS_LAC_124O | E14: TIEZANKRO 3 | F14: Colocation -15% Discount | G14: 44682 | H14: 44712 | I14: 1 | J14: =ROUND(I14,2) -> 1 | K14: 65 | L14: 1744861.9 | M14: =L14*J14 -> 1744861.9 | N14: =M14*$N$5 -> 261729.29 | O14: =M14-N14 -> 1483132.6 | P14: 44682
B15: 9 | C15: PROV ORANGE-COLOC NAWA - Site Blolequin New - MAI 22 | D15: IHS_WRD_004M | E15: Blolequin New | F15: Colocation -15% Discount | G15: 44682 | H15: 44712 | I15: 1 | J15: =ROUND(I15,2) -> 1 | K15: 60 | L15: 1744861.9 | M15: =L15*J15 -> 1744861.9 | N15: =M15*$N$5 -> 261729.29 | O15: =M15-N15 -> 1483132.6 | P15: 44682
B16: 10 | C16: PROV ORANGE-COLOC NAWA - Site ZAGUIETA - MAI 22 | D16: IHS_MRH_081M | E16: ZAGUIETA | F16: Colocation -15% Discount | G16: 44682 | H16: 44712 | I16: 1 | J16: =ROUND(I16,2) -> 1 | K16: 54 | L16: 1744861.9 | M16: =L16*J16 -> 1744861.9 | N16: =M16*$N$5 -> 261729.29 | O16: =M16-N16 -> 1483132.6 | P16: 44682
B17: 11 | C17: PROV ORANGE-COLOC NAWA - BROUSSOUPALEGNOA - MAI 22 | D17: IHS_SBD_099M | E17: BROUSSOUPALEGNOA | F17: Colocation -15% Discount | G17: 44682 | H17: 44712 | I17: 1 | J17: =ROUND(I17,2) -> 1 | K17: 65 | L17: 1744861.9 | M17: =L17*J17 -> 1744861.9 | N17: =M17*$N$5 -> 261729.29 | O17: =M17-N17 -> 1483132.6 | P17: 44682
B18: 12 | C18: PROV ORANGE-COLOC NAWA - M'bahiakro2 - MAI 22 | D18: IHS_NCE_057M | E18: M'bahiakro2 | F18: Colocation -15% Discount | G18: 44682 | H18: 44712 | I18: 1 | J18: =ROUND(I18,2) -> 1 | K18: 45 | L18: 1435883.8 | M18: =L18*J18 -> 1435883.8 | N18: =M18*$N$5 -> 215382.57 | O18: =M18-N18 -> 1220501.2 | P18: 44682
B19: 13 | C19: PROV ORANGE-COLOC NAWA - AYENOUAN - MAI 22 | D19: IHS_SCE_108M | E19: AYENOUAN | F19: Colocation -15% Discount | G19: 44682 | H19: 44712 | I19: 1 | J19: =ROUND(I19,2) -> 1 | K19: 50 | L19: 1744861.9 | M19: =L19*J19 -> 1744861.9 | N19: =M19*$N$5 -> 261729.29 | O19: =M19-N19 -> 1483132.6 | P19: 44682
B20: 14 | C20: PROV ORANGE-COLOC NAWA - GuitryMTN - MAI 22 | D20: IHS_SBD_050M | E20: GuitryMTN | F20: Colocation -15% Discount | G20: 44682 | H20: 44712 | I20: 1 | J20: =ROUND(I20,2) -> 1 | K20: 42 | L20: 1435883.8 | M20: =L20*J20 -> 1435883.8 | N20: =M20*$N$5 -> 215382.57 | O20: =M20-N20 -> 1220501.2 | P20: 44682
B21: 15 | C21: PROV OCI COLOC_Nawa site TOBLY-BANGOLO MAI 22 | D21: IHS_MCY_090M | E21: TOBLY-BANGOLO | F21: Colocation -15% Discount | G21: 44685 | H21: 44712 | I21: =((H21-G21)+1)/31 -> 0.90322581 | J21: =ROUND(I21,2) -> 0.9 | K21: 52 | L21: 1744861.9 | M21: =L21*J21 -> 1570375.7 | N21: =M21*$N$5 -> 235556.36 | O21: =M21-N21 -> 1334819.4 | P21: 44682
B22: 16 | C22: PROV OCI COLOC_Nawa site BANGOLONEW MAI 22 | D22: IHS_DHM_031M | E22: BANGOLONEW | F22: Colocation -15% Discount | G22: 44685 | H22: 44712 | I22: =((H22-G22)+1)/31 -> 0.90322581 | J22: =ROUND(I22,2) -> 0.9 | K22: 63 | L22: 1744861.9 | M22: =L22*J22 -> 1570375.7 | N22: =M22*$N$5 -> 235556.36 | O22: =M22-N22 -> 1334819.4 | P22: 44682
B23: 17 | C23: PROV OCI COLOC_Nawa site YabayoFO MAI 22 | D23: IHS_BSD_163M | E23: YabayoFO | F23: Colocation -15% Discount | G23: 44685 | H23: 44712 | I23: =((H23-G23)+1)/31 -> 0.90322581 | J23: =ROUND(I23,2) -> 0.9 | K23: 50 | L23: 1744861.9 | M23: =L23*J23 -> 1570375.7 | N23: =M23*$N$5 -> 235556.36 | O23: =M23-N23 -> 1334819.4 | P23: 44682
B24: 18 | C24: PROV OCI COLOC_Nawa site ABOBOCASSE MAI 22 | D24: IHS_LGN_817M | E24: ABOBOCASSE | F24: Colocation -15% Discount | G24: 44684 | H24: 44712 | I24: =((H24-G24)+1)/31 -> 0.93548387 | J24: =ROUND(I24,2) -> 0.94 | K24: 12 | L24: 895360 | M24: =L24*J24 -> 841638.4 | N24: =M24*$N$5 -> 126245.76 | O24: =M24-N24 -> 715392.64 | P24: 44682
B25: 19 | C25: PROV OCI COLOC_Nawa site SIBABLY MAI 22 | D25: IHS_MCY_088M | E25: SIBABLY | F25: Colocation -15% Discount | G25: 44685 | H25: 44712 | I25: =((H25-G25)+1)/31 -> 0.90322581 | J25: =ROUND(I25,2) -> 0.9 | K25: 52 | L25: 1744861.9 | M25: =L25*J25 -> 1570375.7 | N25: =M25*$N$5 -> 235556.36 | O25: =M25-N25 -> 1334819.4 | P25: 44682
B26: 20 | C26: PROV OCI COLOC_Nawa site AboboSud MAI 22 | D26: IHS_LGN_562M | E26: AboboSud | F26: Colocation -15% Discount | G26: 44684 | H26: 44712 | I26: =((H26-G26)+1)/31 -> 0.93548387 | J26: =ROUND(I26,2) -> 0.94 | K26: 6 | L26: 895360 | M26: =L26*J26 -> 841638.4 | N26: =M26*$N$5 -> 126245.76 | O26: =M26-N26 -> 715392.64 | P26: 44682
B27: 21 | C27: PROV OCI COLOC_Nawa site DerRail MAI 22 | D27: IHS_LGN_532M | E27: DerRail | F27: Colocation -15% Discount | G27: 44684 | H27: 44712 | I27: =((H27-G27)+1)/31 -> 0.93548387 | J27: =ROUND(I27,2) -> 0.94 | K27: 22 | L27: 1215614.7 | M27: =L27*J27 -> 1142677.8 | N27: =M27*$N$5 -> 171401.67 | O27: =M27-N27 -> 971276.15 | P27: 44682
B28: 22 | C28: PROV OCI COLOC_Nawa site YAO DANKRO MAI 22 | D28: IHS_BSD_235M | E28: YAO DANKRO | F28: Colocation -15% Discount | G28: 44685 | H28: 44712 | I28: =((H28-G28)+1)/31 -> 0.90322581 | J28: =ROUND(I28,2) -> 0.9 | K28: 55 | L28: 1744861.9 | M28: =L28*J28 -> 1570375.7 | N28: =M28*$N$5 -> 235556.36 | O28: =M28-N28 -> 1334819.4 | P28: 44682
B29: 23 | C29: PROV OCI COLOC_Nawa site AboboSteFoi MAI 22 | D29: IHS_LGN_618M | E29: AboboSteFoi | F29: Colocation -15% Discount | G29: 44684 | H29: 44712 | I29: =((H29-G29)+1)/31 -> 0.93548387 | J29: =ROUND(I29,2) -> 0.94 | K29: 9 | L29: 895360 | M29: =L29*J29 -> 841638.4 | N29: =M29*$N$5 -> 126245.76 | O29: =M29-N29 -> 715392.64 | P29: 44682
B30: 24 | C30: PROV OCI COLOC_Nawa site SOKROUGBAN MAI 22 | D30: IHS_WRD_061M | E30: SOKROUGBAN | F30: Colocation -15% Discount | G30: 44685 | H30: 44712 | I30: =((H30-G30)+1)/31 -> 0.90322581 | J30: =ROUND(I30,2) -> 0.9 | K30: 57 | L30: 1744861.9 | M30: =L30*J30 -> 1570375.7 | N30: =M30*$N$5 -> 235556.36 | O30: =M30-N30 -> 1334819.4 | P30: 44682
B31: 25 | C31: PROV ORANGE-COLOC NAWA - Site TIEZANKRO 3 - JUIN 22 | D31: IHS_LAC_124O | E31: TIEZANKRO 3 | F31: Colocation -15% Discount | G31: 44713 | H31: 31/06/2022 | I31: 1 | J31: 1 | K31: 65 | L31: 1744861.9 | M31: =L31*J31 -> 1744861.9 | N31: =M31*$N$5 -> 261729.29 | O31: =M31-N31 -> 1483132.6 | P31: 44713
B32: 26 | C32: PROV ORANGE-COLOC NAWA - Site Blolequin New - JUIN 22 | D32: IHS_WRD_004M | E32: Blolequin New | F32: Colocation -15% Discount | G32: 44713 | H32: 31/06/2022 | I32: 1 | J32: 1 | K32: 60 | L32: 1744861.9 | M32: =L32*J32 -> 1744861.9 | N32: =M32*$N$5 -> 261729.29 | O32: =M32-N32 -> 1483132.6 | P32: 44713
B33: 27 | C33: PROV ORANGE-COLOC NAWA - Site ZAGUIETA - JUIN 22 | D33: IHS_MRH_081M | E33: ZAGUIETA | F33: Colocation -15% Discount | G33: 44713 | H33: 31/06/2022 | I33: 1 | J33: 1 | K33: 54 | L33: 1744861.9 | M33: =L33*J33 -> 1744861.9 | N33: =M33*$N$5 -> 261729.29 | O33: =M33-N33 -> 1483132.6 | P33: 44713
B34: 28 | C34: PROV ORANGE-COLOC NAWA - BROUSSOUPALEGNOA - JUIN 22 | D34: IHS_SBD_099M | E34: BROUSSOUPALEGNOA | F34: Colocation -15% Discount | G34: 44713 | H34: 31/06/2022 | I34: 1 | J34: 1 | K34: 65 | L34: 1744861.9 | M34: =L34*J34 -> 1744861.9 | N34: =M34*$N$5 -> 261729.29 | O34: =M34-N34 -> 1483132.6 | P34: 44713
B35: 29 | C35: PROV ORANGE-COLOC NAWA - M'bahiakro2 - JUIN 22 | D35: IHS_NCE_057M | E35: M'bahiakro2 | F35: Colocation -15% Discount | G35: 44713 | H35: 31/06/2022 | I35: 1 | J35: 1 | K35: 45 | L35: 1435883.8 | M35: =L35*J35 -> 1435883.8 | N35: =M35*$N$5 -> 215382.57 | O35: =M35-N35 -> 1220501.2 | P35: 44713
B36: 30 | C36: PROV ORANGE-COLOC NAWA - AYENOUAN - JUIN 22 | D36: IHS_SCE_108M | E36: AYENOUAN | F36: Colocation -15% Discount | G36: 44713 | H36: 31/06/2022 | I36: 1 | J36: 1 | K36: 50 | L36: 1744861.9 | M36: =L36*J36 -> 1744861.9 | N36: =M36*$N$5 -> 261729.29 | O36: =M36-N36 -> 1483132.6 | P36: 44713
B37: 31 | C37: PROV ORANGE-COLOC NAWA - GuitryMTN - JUIN 22 | D37: IHS_SBD_050M | E37: GuitryMTN | F37: Colocation -15% Discount | G37: 44713 | H37: 31/06/2022 | I37: 1 | J37: 1 | K37: 42 | L37: 1435883.8 | M37: =L37*J37 -> 1435883.8 | N37: =M37*$N$5 -> 215382.57 | O37: =M37-N37 -> 1220501.2 | P37: 44713
B38: 32 | C38: PROV OCI COLOC_Nawa site TOBLY-BANGOLO JUIN 22 | D38: IHS_MCY_090M | E38: TOBLY-BANGOLO | F38: Colocation -15% Discount | G38: 44713 | H38: 31/06/2022 | I38: 1 | J38: 1 | K38: 52 | L38: 1744861.9 | M38: =L38*J38 -> 1744861.9 | N38: =M38*$N$5 -> 261729.29 | O38: =M38-N38 -> 1483132.6 | P38: 44713
B39: 33 | C39: PROV OCI COLOC_Nawa site BANGOLONEW JUIN 22 | D39: IHS_DHM_031M | E39: BANGOLONEW | F39: Colocation -15% Discount | G39: 44713 | H39: 31/06/2022 | I39: 1 | J39: 1 | K39: 63 | L39: 1744861.9 | M39: =L39*J39 -> 1744861.9 | N39: =M39*$N$5 -> 261729.29 | O39: =M39-N39 -> 1483132.6 | P39: 44713
B40: 34 | C40: PROV OCI COLOC_Nawa site YabayoFO JUIN 22 | D40: IHS_BSD_163M | E40: YabayoFO | F40: Colocation -15% Discount | G40: 44713 | H40: 31/06/2022 | I40: 1 | J40: 1 | K40: 50 | L40: 1744861.9 | M40: =L40*J40 -> 1744861.9 | N40: =M40*$N$5 -> 261729.29 | O40: =M40-N40 -> 1483132.6 | P40: 44713
B41: 35 | C41: PROV OCI COLOC_Nawa site ABOBOCASSE JUIN 22 | D41: IHS_LGN_817M | E41: ABOBOCASSE | F41: Colocation -15% Discount | G41: 44713 | H41: 31/06/2022 | I41: 1 | J41: 1 | K41: 12 | L41: 895360 | M41: =L41*J41 -> 895360 | N41: =M41*$N$5 -> 134304 | O41: =M41-N41 -> 761056 | P41: 44713
B42: 36 | C42: PROV OCI COLOC_Nawa site SIBABLY JUIN 22 | D42: IHS_MCY_088M | E42: SIBABLY | F42: Colocation -15% Discount | G42: 44713 | H42: 31/06/2022 | I42: 1 | J42: 1 | K42: 52 | L42: 1744861.9 | M42: =L42*J42 -> 1744861.9 | N42: =M42*$N$5 -> 261729.29 | O42: =M42-N42 -> 1483132.6 | P42: 44713
... B47: 41 | C47: PROV OCI COLOC_Nawa site SOKROUGBAN JUIN 22 | D47: IHS_WRD_061M | E47: SOKROUGBAN | F47: Colocation -15% Discount | G47: 44713 | H47: 31/06/2022 | I47: 1 | J47: 1 | K47: 57 | L47: 1744861.9 | M47: =L47*J47 -> 1744861.9 | N47: =M47*$N$5 -> 261729.29 | O47: =M47-N47 -> 1483132.6 | P47: 44713
B48: 42 | C48: PROV ORANGE-COLOC NAWA - Site TIEZANKRO 3 - JUILLET 22 | D48: IHS_LAC_124O | E48: TIEZANKRO 3 | F48: Colocation -15% Discount | G48: 44743 | H48: 44773 | I48: 1 | J48: 1 | K48: 65 | L48: 1744861.9 | M48: =L48*J48 -> 1744861.9 | N48: =M48*$N$5 -> 261729.29 | O48: =M48-N48 -> 1483132.6 | P48: 44743
...

Sheet PROV 13 SITES BTS Nawa 22-23
B5: PV OCI PROJET 13 SITES BTS NAWA ( en attente du contrat signé pour facturation ) | N5: 0.1 | O5: Provisions
B6: S/N | C6: MOIS | D6: CODE IHS | E6: NOM DU SITE | F6: DESCRIPTION | G6: DATE DE DEBUT | H6: DATE DE FIN | I6: MOIS | J6: MOIS (Two decimals) | K6: HAUTEUR | L6: PU | M6: TOTAL | N6: 10% Discount | O6: MONTANT | P6: PERIODE
B7: 1 | C7: PROV ORANGE - BTS NAWA BEREBY_BIS - SEP 22 | D7: IHS_BSD_259O | E7: BEREBY_BIS | F7: BTS -10% Discount | G7: 44817 | H7: 44834 | I7: =((H7-G7)+1)/30 -> 0.6 | J7: =ROUND(I7,2) -> 0.6 | K7: 32 | L7: 1215614.7 | M7: =L7*J7 -> 729368.83 | N7: =M7*$N$5 -> 72936.883 | O7: =M7-N7 -> 656431.94 | P7: 44805
B8: 2 | C8: PROV ORANGE - BTS NAWA KANI_BIS - SEP 22 | D8: IHS_WRD_064O | E8: KANI_BIS | F8: BTS -10% Discount | G8: 44817 | H8: 44834 | I8: =((H8-G8)+1)/30 -> 0.6 | J8: =ROUND(I8,2) -> 0.6 | K8: 32 | L8: 1215614.7 | M8: =L8*J8 -> 729368.83 | N8: =M8*$N$5 -> 72936.883 | O8: =M8-N8 -> 656431.94 | P8: 44805
B9: 3 | C9: PROV ORANGE - BTS NAWA POGO_BIS - SEP 22 | D9: IHS_SVN_179O | E9: POGO_BIS | F9: BTS -10% Discount | G9: 44817 | H9: 44834 | I9: =((H9-G9)+1)/30 -> 0.6 | J9: =ROUND(I9,2) -> 0.6 | K9: 32 | L9: 1215614.7 | M9: =L9*J9 -> 729368.83 | N9: =M9*$N$5 -> 72936.883 | O9: =M9-N9 -> 656431.94 | P9: 44805
B10: 4 | C10: PROV ORANGE - BTS NAWA TINGRELA_BIS - SEP 22 | D10: IHS_SVN_177O | E10: TINGRELA_BIS | F10: BTS -10% Discount | G10: 44817 | H10: 44834 | I10: =((H10-G10)+1)/30 -> 0.6 | J10: =ROUND(I10,2) -> 0.6 | K10: 32 | L10: 1215614.7 | M10: =L10*J10 -> 729368.83 | N10: =M10*$N$5 -> 72936.883 | O10: =M10-N10 -> 656431.94 | P10: 44805
B11: 5 | C11: PROV ORANGE - BTS NAWA TOULEUPLEU_BIS - SEP 22 | D11: IHS_MCY_094O | E11: TOULEUPLEU_BIS | F11: BTS -10% Discount | G11: 44817 | H11: 44834 | I11: =((H11-G11)+1)/30 -> 0.6 | J11: =ROUND(I11,2) -> 0.6 | K11: 32 | L11: 1215614.7 | M11: =L11*J11 -> 729368.83 | N11: =M11*$N$5 -> 72936.883 | O11: =M11-N11 -> 656431.94 | P11: 44805
B12: 6 | C12: PROV ORANGE - BTS NAWA TAI_BIS - SEP 22 | D12: IHS_MCY_093O | E12: TAI_BIS | F12: BTS -10% Discount | G12: 44810 | H12: 44834 | I12: =((H12-G12)+1)/30 -> 0.83333333 | J12: =ROUND(I12,2) -> 0.83 | K12: 32 | L12: 1215614.7 | M12: =L12*J12 -> 1008960.2 | N12: =M12*$N$5 -> 100896.02 | O12: =M12-N12 -> 908064.19 | P12: 44805
B13: 7 | C13: PROV ORANGE - BTS NAWA NOE_BIS - SEP 22 | D13: IHS_SCE_117O | E13: NOE_BIS | F13: BTS -10% Discount | G13: 44810 | H13: 44834 | I13: =((H13-G13)+1)/30 -> 0.83333333 | J13: =ROUND(I13,2) -> 0.83 | K13: 32 | L13: 1215614.7 | M13: =L13*J13 -> 1008960.2 | N13: =M13*$N$5 -> 100896.02 | O13: =M13-N13 -> 908064.19 | P13: 44805
B14: 8 | C14: PROV ORANGE - BTS NAWA KONG_BIS - SEP 22 | D14: IHS_SVN_142O | E14: KONG_BIS | F14: BTS -10% Discount | G14: 44810 | H14: 44834 | I14: =((H14-G14)+1)/30 -> 0.83333333 | J14: =ROUND(I14,2) -> 0.83 | K14: 32 | L14: 1215614.7 | M14: =L14*J14 -> 1008960.2 | N14: =M14*$N$5 -> 100896.02 | O14: =M14-N14 -> 908064.19 | P14: 44805
B15: 9 | C15: PROV ORANGE - BTS NAWA TORTIYA_BIS - SEP 22 | D15: IHS_VDB_144O | E15: TORTIYA_BIS | F15: BTS -10% Discount | G15: 44810 | H15: 44834 | I15: =((H15-G15)+1)/30 -> 0.83333333 | J15: =ROUND(I15,2) -> 0.83 | K15: 32 | L15: 1215614.7 | M15: =L15*J15 -> 1008960.2 | N15: =M15*$N$5 -> 100896.02 | O15: =M15-N15 -> 908064.19 | P15: 44805
B16: 10 | C16: PROV ORANGE - BTS NAWA NIAKARA_BIS - SEP 22 | D16: IHS_VDB_150O | E16: NIAKARA_BIS | F16: BTS -10% Discount | G16: 44810 | H16: 44834 | I16: =((H16-G16)+1)/30 -> 0.83333333 | J16: =ROUND(I16,2) -> 0.83 | K16: 32 | L16: 1215614.7 | M16: =L16*J16 -> 1008960.2 | N16: =M16*$N$5 -> 100896.02 | O16: =M16-N16 -> 908064.19 | P16: 44805
B17: 11 | C17: PROV ORANGE - BTS NAWA DABAKALA_BIS - SEP 22 | D17: IHS_VDB_154O | E17: DABAKALA_BIS | F17: BTS -10% Discount | G17: 44810 | H17: 44834 | I17: =((H17-G17)+1)/30 -> 0.83333333 | J17: =ROUND(I17,2) -> 0.83 | K17: 32 | L17: 1215614.7 | M17: =L17*J17 -> 1008960.2 | N17: =M17*$N$5 -> 100896.02 | O17: =M17-N17 -> 908064.19 | P17: 44805
B18: 12 | C18: PROV ORANGE - BTS NAWA DOROPO_BIS - SEP 22 | D18: IHS_ZNZ_104O | E18: DOROPO_BIS | F18: BTS -10% Discount | G18: 44810 | H18: 44834 | I18: =((H18-G18)+1)/30 -> 0.83333333 | J18: =ROUND(I18,2) -> 0.83 | K18: 42 | L18: 1435883.8 | M18: =L18*J18 -> 1191783.5 | N18: =M18*$N$5 -> 119178.35 | O18: =M18-N18 -> 1072605.2 | P18: 44805
B19: 13 | C19: PROV ORANGE - BTS NAWA BEREBY_BIS - OCT 22 | D19: IHS_BSD_259O | E19: BEREBY_BIS | F19: BTS -10% Discount | G19: 44835 | H19: 44865 | I19: 1 | J19: =ROUND(I19,2) -> 1 | K19: 32 | L19: 1215614.7 | M19: =L19*J19 -> 1215614.7 | N19: =M19*$N$5 -> 121561.47 | O19: =M19-N19 -> 1094053.2 | P19: 44835
